[2024-11-01T14:13:26.927+0000] {local_task_job_runner.py:123} INFO - ::group::Pre task execution logs
[2024-11-01T14:13:26.951+0000] {taskinstance.py:2612} INFO - Dependencies all met for dep_context=non-requeueable deps ti=<TaskInstance: main_dag.laptop_scraping_tasks.scrape_cellphones manual__2024-11-01T14:13:25.837529+00:00 [queued]>
[2024-11-01T14:13:26.962+0000] {taskinstance.py:2612} INFO - Dependencies all met for dep_context=requeueable deps ti=<TaskInstance: main_dag.laptop_scraping_tasks.scrape_cellphones manual__2024-11-01T14:13:25.837529+00:00 [queued]>
[2024-11-01T14:13:26.963+0000] {taskinstance.py:2865} INFO - Starting attempt 1 of 2
[2024-11-01T14:13:26.978+0000] {taskinstance.py:2888} INFO - Executing <Task(BashOperator): laptop_scraping_tasks.scrape_cellphones> on 2024-11-01 14:13:25.837529+00:00
[2024-11-01T14:13:26.983+0000] {standard_task_runner.py:72} INFO - Started process 4913 to run task
[2024-11-01T14:13:26.986+0000] {standard_task_runner.py:104} INFO - Running: ['***', 'tasks', 'run', 'main_dag', 'laptop_scraping_tasks.scrape_cellphones', 'manual__2024-11-01T14:13:25.837529+00:00', '--job-id', '3', '--raw', '--subdir', 'DAGS_FOLDER/main_dag.py', '--cfg-path', '/tmp/tmpef4llt3_']
[2024-11-01T14:13:26.990+0000] {standard_task_runner.py:105} INFO - Job 3: Subtask laptop_scraping_tasks.scrape_cellphones
[2024-11-01T14:13:27.070+0000] {task_command.py:467} INFO - Running <TaskInstance: main_dag.laptop_scraping_tasks.scrape_cellphones manual__2024-11-01T14:13:25.837529+00:00 [running]> on host b3b9ba79aa5d
[2024-11-01T14:13:27.283+0000] {taskinstance.py:3131} INFO - Exporting env vars: AIRFLOW_CTX_DAG_OWNER='veil' AIRFLOW_CTX_DAG_ID='main_dag' AIRFLOW_CTX_TASK_ID='laptop_scraping_tasks.scrape_cellphones' AIRFLOW_CTX_EXECUTION_DATE='2024-11-01T14:13:25.837529+00:00' AIRFLOW_CTX_TRY_NUMBER='1' AIRFLOW_CTX_DAG_RUN_ID='manual__2024-11-01T14:13:25.837529+00:00'
[2024-11-01T14:13:27.284+0000] {taskinstance.py:731} INFO - ::endgroup::
[2024-11-01T14:13:27.300+0000] {subprocess.py:63} INFO - Tmp dir root location: /tmp
[2024-11-01T14:13:27.301+0000] {subprocess.py:75} INFO - Running command: ['/usr/bin/bash', '-c', 'cd /app/scraper && scrapy crawl cellphones_spider -O ../temp/cellphones_data.json']
[2024-11-01T14:13:27.307+0000] {subprocess.py:86} INFO - Output:
[2024-11-01T14:27:38.459+0000] {local_task_job_runner.py:346} WARNING - State of this instance has been externally set to None. Terminating instance.
[2024-11-01T14:27:38.461+0000] {local_task_job_runner.py:245} INFO - ::endgroup::
[2024-11-01T14:27:38.464+0000] {process_utils.py:132} INFO - Sending 15 to group 4913. PIDs of all processes in the group: [4952, 4962, 4978, 5181, 5209, 5281, 5584, 6220, 6249, 39647, 39684, 39707, 39730, 39814, 39853, 4913]
[2024-11-01T14:27:38.467+0000] {process_utils.py:87} INFO - Sending the signal 15 to group 4913
[2024-11-01T14:27:38.471+0000] {taskinstance.py:3092} ERROR - Received SIGTERM. Terminating subprocesses.
[2024-11-01T14:27:38.481+0000] {subprocess.py:104} INFO - Sending SIGTERM signal to process group
[2024-11-01T14:27:38.521+0000] {process_utils.py:80} INFO - Process psutil.Process(pid=5181, status='terminated', started='14:13:28') (5181) terminated with exit code None
[2024-11-01T14:27:38.522+0000] {process_utils.py:80} INFO - Process psutil.Process(pid=39814, status='terminated', started='14:27:56') (39814) terminated with exit code None
[2024-11-01T14:27:38.523+0000] {process_utils.py:80} INFO - Process psutil.Process(pid=6220, status='terminated', started='14:13:36') (6220) terminated with exit code None
[2024-11-01T14:27:38.551+0000] {taskinstance.py:3310} ERROR - Task failed with exception
Traceback (most recent call last):
  File "/usr/local/lib/python3.11/site-packages/airflow/models/taskinstance.py", line 767, in _execute_task
    result = _execute_callable(context=context, **execute_callable_kwargs)
             ^^^^^^^^^^^^^^^^^^^^^^^^^^^^^^^^^^^^^^^^^^^^^^^^^^^^^^^^^^^^^
  File "/usr/local/lib/python3.11/site-packages/airflow/models/taskinstance.py", line 733, in _execute_callable
    return ExecutionCallableRunner(
           ^^^^^^^^^^^^^^^^^^^^^^^^
  File "/usr/local/lib/python3.11/site-packages/airflow/utils/operator_helpers.py", line 252, in run
    return self.func(*args, **kwargs)
           ^^^^^^^^^^^^^^^^^^^^^^^^^^
  File "/usr/local/lib/python3.11/site-packages/airflow/models/baseoperator.py", line 406, in wrapper
    return func(self, *args, **kwargs)
           ^^^^^^^^^^^^^^^^^^^^^^^^^^^
  File "/usr/local/lib/python3.11/site-packages/airflow/operators/bash.py", line 240, in execute
    result = self.subprocess_hook.run_command(
             ^^^^^^^^^^^^^^^^^^^^^^^^^^^^^^^^^
  File "/usr/local/lib/python3.11/site-packages/airflow/hooks/subprocess.py", line 91, in run_command
    for raw_line in iter(self.sub_process.stdout.readline, b""):
  File "/usr/local/lib/python3.11/site-packages/airflow/models/taskinstance.py", line 3094, in signal_handler
    raise AirflowTaskTerminated("Task received SIGTERM signal")
airflow.exceptions.AirflowTaskTerminated: Task received SIGTERM signal
[2024-11-01T14:27:38.563+0000] {taskinstance.py:1225} INFO - Marking task as UP_FOR_RETRY. dag_id=main_dag, task_id=laptop_scraping_tasks.scrape_cellphones, run_id=manual__2024-11-01T14:13:25.837529+00:00, execution_date=20241101T141325, start_date=20241101T141326, end_date=20241101T142738
[2024-11-01T14:27:38.599+0000] {taskinstance.py:340} INFO - ::group::Post task execution logs
[2024-11-01T14:27:38.600+0000] {standard_task_runner.py:124} ERROR - Failed to execute job 3 for task laptop_scraping_tasks.scrape_cellphones ((psycopg2.errors.ForeignKeyViolation) insert or update on table "task_fail" violates foreign key constraint "task_fail_ti_fkey"
DETAIL:  Key (dag_id, task_id, run_id, map_index)=(main_dag, laptop_scraping_tasks.scrape_cellphones, manual__2024-11-01T14:13:25.837529+00:00, -1) is not present in table "task_instance".

[SQL: INSERT INTO task_fail (task_id, dag_id, run_id, map_index, start_date, end_date, duration) VALUES (%(task_id)s, %(dag_id)s, %(run_id)s, %(map_index)s, %(start_date)s, %(end_date)s, %(duration)s) RETURNING task_fail.id]
[parameters: {'task_id': 'laptop_scraping_tasks.scrape_cellphones', 'dag_id': 'main_dag', 'run_id': 'manual__2024-11-01T14:13:25.837529+00:00', 'map_index': -1, 'start_date': datetime.datetime(2024, 11, 1, 14, 13, 26, 952713, tzinfo=Timezone('UTC')), 'end_date': datetime.datetime(2024, 11, 1, 14, 27, 38, 560526, tzinfo=Timezone('UTC')), 'duration': 851}]
(Background on this error at: https://sqlalche.me/e/14/gkpj); 4913)
Traceback (most recent call last):
  File "/usr/local/lib/python3.11/site-packages/airflow/models/taskinstance.py", line 273, in _run_raw_task
    TaskInstance._execute_task_with_callbacks(
  File "/usr/local/lib/python3.11/site-packages/airflow/models/taskinstance.py", line 3158, in _execute_task_with_callbacks
    result = self._execute_task(context, task_orig)
             ^^^^^^^^^^^^^^^^^^^^^^^^^^^^^^^^^^^^^^
  File "/usr/local/lib/python3.11/site-packages/airflow/models/taskinstance.py", line 3182, in _execute_task
    return _execute_task(self, context, task_orig)
           ^^^^^^^^^^^^^^^^^^^^^^^^^^^^^^^^^^^^^^^
  File "/usr/local/lib/python3.11/site-packages/airflow/models/taskinstance.py", line 767, in _execute_task
    result = _execute_callable(context=context, **execute_callable_kwargs)
             ^^^^^^^^^^^^^^^^^^^^^^^^^^^^^^^^^^^^^^^^^^^^^^^^^^^^^^^^^^^^^
  File "/usr/local/lib/python3.11/site-packages/airflow/models/taskinstance.py", line 733, in _execute_callable
    return ExecutionCallableRunner(
           ^^^^^^^^^^^^^^^^^^^^^^^^
  File "/usr/local/lib/python3.11/site-packages/airflow/utils/operator_helpers.py", line 252, in run
    return self.func(*args, **kwargs)
           ^^^^^^^^^^^^^^^^^^^^^^^^^^
  File "/usr/local/lib/python3.11/site-packages/airflow/models/baseoperator.py", line 406, in wrapper
    return func(self, *args, **kwargs)
           ^^^^^^^^^^^^^^^^^^^^^^^^^^^
  File "/usr/local/lib/python3.11/site-packages/airflow/operators/bash.py", line 240, in execute
    result = self.subprocess_hook.run_command(
             ^^^^^^^^^^^^^^^^^^^^^^^^^^^^^^^^^
  File "/usr/local/lib/python3.11/site-packages/airflow/hooks/subprocess.py", line 91, in run_command
    for raw_line in iter(self.sub_process.stdout.readline, b""):
  File "/usr/local/lib/python3.11/site-packages/airflow/models/taskinstance.py", line 3094, in signal_handler
    raise AirflowTaskTerminated("Task received SIGTERM signal")
airflow.exceptions.AirflowTaskTerminated: Task received SIGTERM signal

During handling of the above exception, another exception occurred:

Traceback (most recent call last):
  File "/usr/local/lib/python3.11/site-packages/sqlalchemy/engine/base.py", line 1910, in _execute_context
    self.dialect.do_execute(
  File "/usr/local/lib/python3.11/site-packages/sqlalchemy/engine/default.py", line 736, in do_execute
    cursor.execute(statement, parameters)
psycopg2.errors.ForeignKeyViolation: insert or update on table "task_fail" violates foreign key constraint "task_fail_ti_fkey"
DETAIL:  Key (dag_id, task_id, run_id, map_index)=(main_dag, laptop_scraping_tasks.scrape_cellphones, manual__2024-11-01T14:13:25.837529+00:00, -1) is not present in table "task_instance".


The above exception was the direct cause of the following exception:

Traceback (most recent call last):
  File "/usr/local/lib/python3.11/site-packages/airflow/task/task_runner/standard_task_runner.py", line 117, in _start_by_fork
    ret = args.func(args, dag=self.dag)
          ^^^^^^^^^^^^^^^^^^^^^^^^^^^^^
  File "/usr/local/lib/python3.11/site-packages/airflow/cli/cli_config.py", line 49, in command
    return func(*args, **kwargs)
           ^^^^^^^^^^^^^^^^^^^^^
  File "/usr/local/lib/python3.11/site-packages/airflow/utils/cli.py", line 115, in wrapper
    return f(*args, **kwargs)
           ^^^^^^^^^^^^^^^^^^
  File "/usr/local/lib/python3.11/site-packages/airflow/cli/commands/task_command.py", line 483, in task_run
    task_return_code = _run_task_by_selected_method(args, _dag, ti)
                       ^^^^^^^^^^^^^^^^^^^^^^^^^^^^^^^^^^^^^^^^^^^^
  File "/usr/local/lib/python3.11/site-packages/airflow/cli/commands/task_command.py", line 256, in _run_task_by_selected_method
    return _run_raw_task(args, ti)
           ^^^^^^^^^^^^^^^^^^^^^^^
  File "/usr/local/lib/python3.11/site-packages/airflow/cli/commands/task_command.py", line 341, in _run_raw_task
    return ti._run_raw_task(
           ^^^^^^^^^^^^^^^^^
  File "/usr/local/lib/python3.11/site-packages/airflow/utils/session.py", line 97, in wrapper
    return func(*args, session=session, **kwargs)
           ^^^^^^^^^^^^^^^^^^^^^^^^^^^^^^^^^^^^^^
  File "/usr/local/lib/python3.11/site-packages/airflow/models/taskinstance.py", line 3004, in _run_raw_task
    return _run_raw_task(
           ^^^^^^^^^^^^^^
  File "/usr/local/lib/python3.11/site-packages/airflow/models/taskinstance.py", line 327, in _run_raw_task
    ti.handle_failure(e, test_mode, context, session=session)
  File "/usr/local/lib/python3.11/site-packages/airflow/utils/session.py", line 94, in wrapper
    return func(*args, **kwargs)
           ^^^^^^^^^^^^^^^^^^^^^
  File "/usr/local/lib/python3.11/site-packages/airflow/models/taskinstance.py", line 3427, in handle_failure
    _handle_failure(
  File "/usr/local/lib/python3.11/site-packages/airflow/utils/session.py", line 94, in wrapper
    return func(*args, **kwargs)
           ^^^^^^^^^^^^^^^^^^^^^
  File "/usr/local/lib/python3.11/site-packages/airflow/api_internal/internal_api_call.py", line 139, in wrapper
    return func(*args, **kwargs)
           ^^^^^^^^^^^^^^^^^^^^^
  File "/usr/local/lib/python3.11/site-packages/airflow/models/taskinstance.py", line 1243, in _handle_failure
    TaskInstance.save_to_db(failure_context["ti"], session)
  File "/usr/local/lib/python3.11/site-packages/airflow/api_internal/internal_api_call.py", line 139, in wrapper
    return func(*args, **kwargs)
           ^^^^^^^^^^^^^^^^^^^^^
  File "/usr/local/lib/python3.11/site-packages/airflow/utils/session.py", line 94, in wrapper
    return func(*args, **kwargs)
           ^^^^^^^^^^^^^^^^^^^^^
  File "/usr/local/lib/python3.11/site-packages/airflow/models/taskinstance.py", line 3399, in save_to_db
    session.flush()
  File "/usr/local/lib/python3.11/site-packages/sqlalchemy/orm/session.py", line 3449, in flush
    self._flush(objects)
  File "/usr/local/lib/python3.11/site-packages/sqlalchemy/orm/session.py", line 3588, in _flush
    with util.safe_reraise():
  File "/usr/local/lib/python3.11/site-packages/sqlalchemy/util/langhelpers.py", line 70, in __exit__
    compat.raise_(
  File "/usr/local/lib/python3.11/site-packages/sqlalchemy/util/compat.py", line 211, in raise_
    raise exception
  File "/usr/local/lib/python3.11/site-packages/sqlalchemy/orm/session.py", line 3549, in _flush
    flush_context.execute()
  File "/usr/local/lib/python3.11/site-packages/sqlalchemy/orm/unitofwork.py", line 456, in execute
    rec.execute(self)
  File "/usr/local/lib/python3.11/site-packages/sqlalchemy/orm/unitofwork.py", line 630, in execute
    util.preloaded.orm_persistence.save_obj(
  File "/usr/local/lib/python3.11/site-packages/sqlalchemy/orm/persistence.py", line 245, in save_obj
    _emit_insert_statements(
  File "/usr/local/lib/python3.11/site-packages/sqlalchemy/orm/persistence.py", line 1238, in _emit_insert_statements
    result = connection._execute_20(
             ^^^^^^^^^^^^^^^^^^^^^^^
  File "/usr/local/lib/python3.11/site-packages/sqlalchemy/engine/base.py", line 1710, in _execute_20
    return meth(self, args_10style, kwargs_10style, execution_options)
           ^^^^^^^^^^^^^^^^^^^^^^^^^^^^^^^^^^^^^^^^^^^^^^^^^^^^^^^^^^^
  File "/usr/local/lib/python3.11/site-packages/sqlalchemy/sql/elements.py", line 334, in _execute_on_connection
    return connection._execute_clauseelement(
           ^^^^^^^^^^^^^^^^^^^^^^^^^^^^^^^^^^
  File "/usr/local/lib/python3.11/site-packages/sqlalchemy/engine/base.py", line 1577, in _execute_clauseelement
    ret = self._execute_context(
          ^^^^^^^^^^^^^^^^^^^^^^
  File "/usr/local/lib/python3.11/site-packages/sqlalchemy/engine/base.py", line 1953, in _execute_context
    self._handle_dbapi_exception(
  File "/usr/local/lib/python3.11/site-packages/sqlalchemy/engine/base.py", line 2134, in _handle_dbapi_exception
    util.raise_(
  File "/usr/local/lib/python3.11/site-packages/sqlalchemy/util/compat.py", line 211, in raise_
    raise exception
  File "/usr/local/lib/python3.11/site-packages/sqlalchemy/engine/base.py", line 1910, in _execute_context
    self.dialect.do_execute(
  File "/usr/local/lib/python3.11/site-packages/sqlalchemy/engine/default.py", line 736, in do_execute
    cursor.execute(statement, parameters)
sqlalchemy.exc.IntegrityError: (psycopg2.errors.ForeignKeyViolation) insert or update on table "task_fail" violates foreign key constraint "task_fail_ti_fkey"
DETAIL:  Key (dag_id, task_id, run_id, map_index)=(main_dag, laptop_scraping_tasks.scrape_cellphones, manual__2024-11-01T14:13:25.837529+00:00, -1) is not present in table "task_instance".

[SQL: INSERT INTO task_fail (task_id, dag_id, run_id, map_index, start_date, end_date, duration) VALUES (%(task_id)s, %(dag_id)s, %(run_id)s, %(map_index)s, %(start_date)s, %(end_date)s, %(duration)s) RETURNING task_fail.id]
[parameters: {'task_id': 'laptop_scraping_tasks.scrape_cellphones', 'dag_id': 'main_dag', 'run_id': 'manual__2024-11-01T14:13:25.837529+00:00', 'map_index': -1, 'start_date': datetime.datetime(2024, 11, 1, 14, 13, 26, 952713, tzinfo=Timezone('UTC')), 'end_date': datetime.datetime(2024, 11, 1, 14, 27, 38, 560526, tzinfo=Timezone('UTC')), 'duration': 851}]
(Background on this error at: https://sqlalche.me/e/14/gkpj)
[2024-11-01T14:27:38.617+0000] {process_utils.py:80} INFO - Process psutil.Process(pid=39853, status='terminated', started='14:27:56') (39853) terminated with exit code None
[2024-11-01T14:27:38.618+0000] {process_utils.py:80} INFO - Process psutil.Process(pid=6249, status='terminated', started='14:13:36') (6249) terminated with exit code None
[2024-11-01T14:27:38.715+0000] {process_utils.py:80} INFO - Process psutil.Process(pid=5281, status='terminated', started='14:13:29') (5281) terminated with exit code None
[2024-11-01T14:27:38.716+0000] {process_utils.py:80} INFO - Process psutil.Process(pid=39684, status='terminated', started='14:27:55') (39684) terminated with exit code None
[2024-11-01T14:27:38.717+0000] {process_utils.py:80} INFO - Process psutil.Process(pid=4978, status='terminated', started='14:13:28') (4978) terminated with exit code None
[2024-11-01T14:27:38.718+0000] {process_utils.py:80} INFO - Process psutil.Process(pid=39730, status='terminated', started='14:27:55') (39730) terminated with exit code None
[2024-11-01T14:27:38.727+0000] {process_utils.py:80} INFO - Process psutil.Process(pid=4913, status='terminated', exitcode=1, started='14:13:26') (4913) terminated with exit code 1
[2024-11-01T14:27:38.729+0000] {process_utils.py:80} INFO - Process psutil.Process(pid=5584, status='terminated', started='14:13:30') (5584) terminated with exit code None
[2024-11-01T14:27:38.733+0000] {process_utils.py:80} INFO - Process psutil.Process(pid=5209, status='terminated', started='14:13:29') (5209) terminated with exit code None
[2024-11-01T14:27:38.735+0000] {process_utils.py:80} INFO - Process psutil.Process(pid=39647, status='terminated', started='14:27:54') (39647) terminated with exit code None
[2024-11-01T14:27:38.737+0000] {process_utils.py:80} INFO - Process psutil.Process(pid=39707, status='terminated', started='14:27:55') (39707) terminated with exit code None
[2024-11-01T14:27:42.464+0000] {standard_task_runner.py:217} INFO - Process not found (most likely exited), stop collecting metrics
[2024-11-01T14:27:44.371+0000] {process_utils.py:80} INFO - Process psutil.Process(pid=4962, status='terminated', started='14:13:27') (4962) terminated with exit code None
[2024-11-01T14:27:44.467+0000] {process_utils.py:80} INFO - Process psutil.Process(pid=4952, status='terminated', started='14:13:26') (4952) terminated with exit code None
