[2024-11-06T03:12:38.593+0000] {local_task_job_runner.py:123} INFO - ::group::Pre task execution logs
[2024-11-06T03:12:38.688+0000] {taskinstance.py:2612} INFO - Dependencies all met for dep_context=non-requeueable deps ti=<TaskInstance: test_dag.database_tasks.check_integrity manual__2024-11-06T02:17:50.795367+00:00 [queued]>
[2024-11-06T03:12:38.694+0000] {taskinstance.py:2612} INFO - Dependencies all met for dep_context=requeueable deps ti=<TaskInstance: test_dag.database_tasks.check_integrity manual__2024-11-06T02:17:50.795367+00:00 [queued]>
[2024-11-06T03:12:38.695+0000] {taskinstance.py:2865} INFO - Starting attempt 2 of 2
[2024-11-06T03:12:38.711+0000] {taskinstance.py:2888} INFO - Executing <Task(PythonOperator): database_tasks.check_integrity> on 2024-11-06 02:17:50.795367+00:00
[2024-11-06T03:12:38.714+0000] {standard_task_runner.py:72} INFO - Started process 32417 to run task
[2024-11-06T03:12:38.717+0000] {standard_task_runner.py:104} INFO - Running: ['***', 'tasks', 'run', 'test_dag', 'database_tasks.check_integrity', 'manual__2024-11-06T02:17:50.795367+00:00', '--job-id', '17', '--raw', '--subdir', 'DAGS_FOLDER/test_dag.py', '--cfg-path', '/tmp/tmpku_1mska']
[2024-11-06T03:12:38.718+0000] {standard_task_runner.py:105} INFO - Job 17: Subtask database_tasks.check_integrity
[2024-11-06T03:12:38.766+0000] {task_command.py:467} INFO - Running <TaskInstance: test_dag.database_tasks.check_integrity manual__2024-11-06T02:17:50.795367+00:00 [running]> on host 64e2411a2cf3
[2024-11-06T03:12:38.835+0000] {taskinstance.py:3131} INFO - Exporting env vars: AIRFLOW_CTX_DAG_OWNER='veil' AIRFLOW_CTX_DAG_ID='test_dag' AIRFLOW_CTX_TASK_ID='database_tasks.check_integrity' AIRFLOW_CTX_EXECUTION_DATE='2024-11-06T02:17:50.795367+00:00' AIRFLOW_CTX_TRY_NUMBER='2' AIRFLOW_CTX_DAG_RUN_ID='manual__2024-11-06T02:17:50.795367+00:00'
[2024-11-06T03:12:38.836+0000] {taskinstance.py:731} INFO - ::endgroup::
[2024-11-06T03:12:38.849+0000] {logging_mixin.py:190} INFO - Connection to PostgreSQL DB successful
[2024-11-06T03:12:38.850+0000] {logging_mixin.py:190} INFO - /app/***/dags/database/integrity_check.py
[2024-11-06T03:12:38.932+0000] {taskinstance.py:3310} ERROR - Task failed with exception
Traceback (most recent call last):
  File "/usr/local/lib/python3.11/site-packages/airflow/models/taskinstance.py", line 767, in _execute_task
    result = _execute_callable(context=context, **execute_callable_kwargs)
             ^^^^^^^^^^^^^^^^^^^^^^^^^^^^^^^^^^^^^^^^^^^^^^^^^^^^^^^^^^^^^
  File "/usr/local/lib/python3.11/site-packages/airflow/models/taskinstance.py", line 733, in _execute_callable
    return ExecutionCallableRunner(
           ^^^^^^^^^^^^^^^^^^^^^^^^
  File "/usr/local/lib/python3.11/site-packages/airflow/utils/operator_helpers.py", line 252, in run
    return self.func(*args, **kwargs)
           ^^^^^^^^^^^^^^^^^^^^^^^^^^
  File "/usr/local/lib/python3.11/site-packages/airflow/models/baseoperator.py", line 406, in wrapper
    return func(self, *args, **kwargs)
           ^^^^^^^^^^^^^^^^^^^^^^^^^^^
  File "/usr/local/lib/python3.11/site-packages/airflow/operators/python.py", line 238, in execute
    return_value = self.execute_callable()
                   ^^^^^^^^^^^^^^^^^^^^^^^
  File "/usr/local/lib/python3.11/site-packages/airflow/operators/python.py", line 256, in execute_callable
    return runner.run(*self.op_args, **self.op_kwargs)
           ^^^^^^^^^^^^^^^^^^^^^^^^^^^^^^^^^^^^^^^^^^^
  File "/usr/local/lib/python3.11/site-packages/airflow/utils/operator_helpers.py", line 252, in run
    return self.func(*args, **kwargs)
           ^^^^^^^^^^^^^^^^^^^^^^^^^^
  File "/app/airflow/dags/database/integrity_check.py", line 125, in check_integrity_all
    _check_integrity(conn,
  File "/app/airflow/dags/database/integrity_check.py", line 110, in _check_integrity
    with open(export_path, 'w') as file:
         ^^^^^^^^^^^^^^^^^^^^^^
FileNotFoundError: [Errno 2] No such file or directory: './database/cpu_integrity_check_result.log'
[2024-11-06T03:12:38.942+0000] {taskinstance.py:1225} INFO - Marking task as FAILED. dag_id=test_dag, task_id=database_tasks.check_integrity, run_id=manual__2024-11-06T02:17:50.795367+00:00, execution_date=20241106T021750, start_date=20241106T031238, end_date=20241106T031238
[2024-11-06T03:12:38.951+0000] {taskinstance.py:340} INFO - ::group::Post task execution logs
[2024-11-06T03:12:38.951+0000] {standard_task_runner.py:124} ERROR - Failed to execute job 17 for task database_tasks.check_integrity ([Errno 2] No such file or directory: './database/cpu_integrity_check_result.log'; 32417)
Traceback (most recent call last):
  File "/usr/local/lib/python3.11/site-packages/airflow/task/task_runner/standard_task_runner.py", line 117, in _start_by_fork
    ret = args.func(args, dag=self.dag)
          ^^^^^^^^^^^^^^^^^^^^^^^^^^^^^
  File "/usr/local/lib/python3.11/site-packages/airflow/cli/cli_config.py", line 49, in command
    return func(*args, **kwargs)
           ^^^^^^^^^^^^^^^^^^^^^
  File "/usr/local/lib/python3.11/site-packages/airflow/utils/cli.py", line 115, in wrapper
    return f(*args, **kwargs)
           ^^^^^^^^^^^^^^^^^^
  File "/usr/local/lib/python3.11/site-packages/airflow/cli/commands/task_command.py", line 483, in task_run
    task_return_code = _run_task_by_selected_method(args, _dag, ti)
                       ^^^^^^^^^^^^^^^^^^^^^^^^^^^^^^^^^^^^^^^^^^^^
  File "/usr/local/lib/python3.11/site-packages/airflow/cli/commands/task_command.py", line 256, in _run_task_by_selected_method
    return _run_raw_task(args, ti)
           ^^^^^^^^^^^^^^^^^^^^^^^
  File "/usr/local/lib/python3.11/site-packages/airflow/cli/commands/task_command.py", line 341, in _run_raw_task
    return ti._run_raw_task(
           ^^^^^^^^^^^^^^^^^
  File "/usr/local/lib/python3.11/site-packages/airflow/utils/session.py", line 97, in wrapper
    return func(*args, session=session, **kwargs)
           ^^^^^^^^^^^^^^^^^^^^^^^^^^^^^^^^^^^^^^
  File "/usr/local/lib/python3.11/site-packages/airflow/models/taskinstance.py", line 3004, in _run_raw_task
    return _run_raw_task(
           ^^^^^^^^^^^^^^
  File "/usr/local/lib/python3.11/site-packages/airflow/models/taskinstance.py", line 273, in _run_raw_task
    TaskInstance._execute_task_with_callbacks(
  File "/usr/local/lib/python3.11/site-packages/airflow/models/taskinstance.py", line 3158, in _execute_task_with_callbacks
    result = self._execute_task(context, task_orig)
             ^^^^^^^^^^^^^^^^^^^^^^^^^^^^^^^^^^^^^^
  File "/usr/local/lib/python3.11/site-packages/airflow/models/taskinstance.py", line 3182, in _execute_task
    return _execute_task(self, context, task_orig)
           ^^^^^^^^^^^^^^^^^^^^^^^^^^^^^^^^^^^^^^^
  File "/usr/local/lib/python3.11/site-packages/airflow/models/taskinstance.py", line 767, in _execute_task
    result = _execute_callable(context=context, **execute_callable_kwargs)
             ^^^^^^^^^^^^^^^^^^^^^^^^^^^^^^^^^^^^^^^^^^^^^^^^^^^^^^^^^^^^^
  File "/usr/local/lib/python3.11/site-packages/airflow/models/taskinstance.py", line 733, in _execute_callable
    return ExecutionCallableRunner(
           ^^^^^^^^^^^^^^^^^^^^^^^^
  File "/usr/local/lib/python3.11/site-packages/airflow/utils/operator_helpers.py", line 252, in run
    return self.func(*args, **kwargs)
           ^^^^^^^^^^^^^^^^^^^^^^^^^^
  File "/usr/local/lib/python3.11/site-packages/airflow/models/baseoperator.py", line 406, in wrapper
    return func(self, *args, **kwargs)
           ^^^^^^^^^^^^^^^^^^^^^^^^^^^
  File "/usr/local/lib/python3.11/site-packages/airflow/operators/python.py", line 238, in execute
    return_value = self.execute_callable()
                   ^^^^^^^^^^^^^^^^^^^^^^^
  File "/usr/local/lib/python3.11/site-packages/airflow/operators/python.py", line 256, in execute_callable
    return runner.run(*self.op_args, **self.op_kwargs)
           ^^^^^^^^^^^^^^^^^^^^^^^^^^^^^^^^^^^^^^^^^^^
  File "/usr/local/lib/python3.11/site-packages/airflow/utils/operator_helpers.py", line 252, in run
    return self.func(*args, **kwargs)
           ^^^^^^^^^^^^^^^^^^^^^^^^^^
  File "/app/airflow/dags/database/integrity_check.py", line 125, in check_integrity_all
    _check_integrity(conn,
  File "/app/airflow/dags/database/integrity_check.py", line 110, in _check_integrity
    with open(export_path, 'w') as file:
         ^^^^^^^^^^^^^^^^^^^^^^
FileNotFoundError: [Errno 2] No such file or directory: './database/cpu_integrity_check_result.log'
[2024-11-06T03:12:38.980+0000] {local_task_job_runner.py:266} INFO - Task exited with return code 1
[2024-11-06T03:12:38.993+0000] {taskinstance.py:3900} INFO - 0 downstream tasks scheduled from follow-on schedule check
[2024-11-06T03:12:38.996+0000] {local_task_job_runner.py:245} INFO - ::endgroup::
