[2024-11-05T15:34:47.261+0000] {local_task_job_runner.py:123} INFO - ::group::Pre task execution logs
[2024-11-05T15:34:47.279+0000] {taskinstance.py:2612} INFO - Dependencies all met for dep_context=non-requeueable deps ti=<TaskInstance: test_dag.database_tasks.create_gpu_specs_table manual__2024-11-05T15:34:45.958374+00:00 [queued]>
[2024-11-05T15:34:47.286+0000] {taskinstance.py:2612} INFO - Dependencies all met for dep_context=requeueable deps ti=<TaskInstance: test_dag.database_tasks.create_gpu_specs_table manual__2024-11-05T15:34:45.958374+00:00 [queued]>
[2024-11-05T15:34:47.287+0000] {taskinstance.py:2865} INFO - Starting attempt 1 of 2
[2024-11-05T15:34:47.297+0000] {taskinstance.py:2888} INFO - Executing <Task(PostgresOperator): database_tasks.create_gpu_specs_table> on 2024-11-05 15:34:45.958374+00:00
[2024-11-05T15:34:47.299+0000] {standard_task_runner.py:72} INFO - Started process 42776 to run task
[2024-11-05T15:34:47.302+0000] {standard_task_runner.py:104} INFO - Running: ['***', 'tasks', 'run', 'test_dag', 'database_tasks.create_gpu_specs_table', 'manual__2024-11-05T15:34:45.958374+00:00', '--job-id', '8', '--raw', '--subdir', 'DAGS_FOLDER/test_dag.py', '--cfg-path', '/tmp/tmpemjezrfn']
[2024-11-05T15:34:47.303+0000] {standard_task_runner.py:105} INFO - Job 8: Subtask database_tasks.create_gpu_specs_table
[2024-11-05T15:34:47.391+0000] {task_command.py:467} INFO - Running <TaskInstance: test_dag.database_tasks.create_gpu_specs_table manual__2024-11-05T15:34:45.958374+00:00 [running]> on host fe7d69d5ba3a
[2024-11-05T15:34:47.499+0000] {taskinstance.py:3131} INFO - Exporting env vars: AIRFLOW_CTX_DAG_OWNER='veil' AIRFLOW_CTX_DAG_ID='test_dag' AIRFLOW_CTX_TASK_ID='database_tasks.create_gpu_specs_table' AIRFLOW_CTX_EXECUTION_DATE='2024-11-05T15:34:45.958374+00:00' AIRFLOW_CTX_TRY_NUMBER='1' AIRFLOW_CTX_DAG_RUN_ID='manual__2024-11-05T15:34:45.958374+00:00'
[2024-11-05T15:34:47.501+0000] {taskinstance.py:731} INFO - ::endgroup::
[2024-11-05T15:34:47.511+0000] {sql.py:278} INFO - Executing: 
        CREATE TABLE gpu_specs_11_2024 (
            name VARCHAR(255) PRIMARY KEY NOT NULL,
            avg_g3d_mark INT,
            bus_interface VARCHAR(50),
            max_memory_size INT,
            core_clock INT,
            max_direct VARCHAR(10),
            open_gl DECIMAL(3, 1),
            max_tdp INT,
            test_directx_9 INT,
            test_directx_10 INT,
            test_directx_11 INT,
            test_directx_12 INT,
            test_gpu_compute INT
        );
        
[2024-11-05T15:34:47.523+0000] {base.py:84} INFO - Retrieving connection 'postgres_default'
[2024-11-05T15:34:47.535+0000] {base.py:84} INFO - Retrieving connection 'postgres_default'
[2024-11-05T15:34:47.543+0000] {sql.py:544} INFO - Running statement: 
        CREATE TABLE gpu_specs_11_2024 (
            name VARCHAR(255) PRIMARY KEY NOT NULL,
            avg_g3d_mark INT,
            bus_interface VARCHAR(50),
            max_memory_size INT,
            core_clock INT,
            max_direct VARCHAR(10),
            open_gl DECIMAL(3, 1),
            max_tdp INT,
            test_directx_9 INT,
            test_directx_10 INT,
            test_directx_11 INT,
            test_directx_12 INT,
            test_gpu_compute INT
        );
        , parameters: None
[2024-11-05T15:34:47.544+0000] {taskinstance.py:3310} ERROR - Task failed with exception
Traceback (most recent call last):
  File "/usr/local/lib/python3.11/site-packages/airflow/models/taskinstance.py", line 767, in _execute_task
    result = _execute_callable(context=context, **execute_callable_kwargs)
             ^^^^^^^^^^^^^^^^^^^^^^^^^^^^^^^^^^^^^^^^^^^^^^^^^^^^^^^^^^^^^
  File "/usr/local/lib/python3.11/site-packages/airflow/models/taskinstance.py", line 733, in _execute_callable
    return ExecutionCallableRunner(
           ^^^^^^^^^^^^^^^^^^^^^^^^
  File "/usr/local/lib/python3.11/site-packages/airflow/utils/operator_helpers.py", line 252, in run
    return self.func(*args, **kwargs)
           ^^^^^^^^^^^^^^^^^^^^^^^^^^
  File "/usr/local/lib/python3.11/site-packages/airflow/models/baseoperator.py", line 406, in wrapper
    return func(self, *args, **kwargs)
           ^^^^^^^^^^^^^^^^^^^^^^^^^^^
  File "/usr/local/lib/python3.11/site-packages/airflow/providers/common/sql/operators/sql.py", line 284, in execute
    output = hook.run(
             ^^^^^^^^^
  File "/usr/local/lib/python3.11/site-packages/airflow/providers/common/sql/hooks/sql.py", line 489, in run
    self._run_command(cur, sql_statement, parameters)
  File "/usr/local/lib/python3.11/site-packages/airflow/providers/common/sql/hooks/sql.py", line 549, in _run_command
    cur.execute(sql_statement)
psycopg2.errors.DuplicateTable: relation "gpu_specs_11_2024" already exists

[2024-11-05T15:34:47.557+0000] {taskinstance.py:1225} INFO - Marking task as UP_FOR_RETRY. dag_id=test_dag, task_id=database_tasks.create_gpu_specs_table, run_id=manual__2024-11-05T15:34:45.958374+00:00, execution_date=20241105T153445, start_date=20241105T153447, end_date=20241105T153447
[2024-11-05T15:34:47.569+0000] {taskinstance.py:340} INFO - ::group::Post task execution logs
[2024-11-05T15:34:47.569+0000] {standard_task_runner.py:124} ERROR - Failed to execute job 8 for task database_tasks.create_gpu_specs_table (relation "gpu_specs_11_2024" already exists
; 42776)
Traceback (most recent call last):
  File "/usr/local/lib/python3.11/site-packages/airflow/task/task_runner/standard_task_runner.py", line 117, in _start_by_fork
    ret = args.func(args, dag=self.dag)
          ^^^^^^^^^^^^^^^^^^^^^^^^^^^^^
  File "/usr/local/lib/python3.11/site-packages/airflow/cli/cli_config.py", line 49, in command
    return func(*args, **kwargs)
           ^^^^^^^^^^^^^^^^^^^^^
  File "/usr/local/lib/python3.11/site-packages/airflow/utils/cli.py", line 115, in wrapper
    return f(*args, **kwargs)
           ^^^^^^^^^^^^^^^^^^
  File "/usr/local/lib/python3.11/site-packages/airflow/cli/commands/task_command.py", line 483, in task_run
    task_return_code = _run_task_by_selected_method(args, _dag, ti)
                       ^^^^^^^^^^^^^^^^^^^^^^^^^^^^^^^^^^^^^^^^^^^^
  File "/usr/local/lib/python3.11/site-packages/airflow/cli/commands/task_command.py", line 256, in _run_task_by_selected_method
    return _run_raw_task(args, ti)
           ^^^^^^^^^^^^^^^^^^^^^^^
  File "/usr/local/lib/python3.11/site-packages/airflow/cli/commands/task_command.py", line 341, in _run_raw_task
    return ti._run_raw_task(
           ^^^^^^^^^^^^^^^^^
  File "/usr/local/lib/python3.11/site-packages/airflow/utils/session.py", line 97, in wrapper
    return func(*args, session=session, **kwargs)
           ^^^^^^^^^^^^^^^^^^^^^^^^^^^^^^^^^^^^^^
  File "/usr/local/lib/python3.11/site-packages/airflow/models/taskinstance.py", line 3004, in _run_raw_task
    return _run_raw_task(
           ^^^^^^^^^^^^^^
  File "/usr/local/lib/python3.11/site-packages/airflow/models/taskinstance.py", line 273, in _run_raw_task
    TaskInstance._execute_task_with_callbacks(
  File "/usr/local/lib/python3.11/site-packages/airflow/models/taskinstance.py", line 3158, in _execute_task_with_callbacks
    result = self._execute_task(context, task_orig)
             ^^^^^^^^^^^^^^^^^^^^^^^^^^^^^^^^^^^^^^
  File "/usr/local/lib/python3.11/site-packages/airflow/models/taskinstance.py", line 3182, in _execute_task
    return _execute_task(self, context, task_orig)
           ^^^^^^^^^^^^^^^^^^^^^^^^^^^^^^^^^^^^^^^
  File "/usr/local/lib/python3.11/site-packages/airflow/models/taskinstance.py", line 767, in _execute_task
    result = _execute_callable(context=context, **execute_callable_kwargs)
             ^^^^^^^^^^^^^^^^^^^^^^^^^^^^^^^^^^^^^^^^^^^^^^^^^^^^^^^^^^^^^
  File "/usr/local/lib/python3.11/site-packages/airflow/models/taskinstance.py", line 733, in _execute_callable
    return ExecutionCallableRunner(
           ^^^^^^^^^^^^^^^^^^^^^^^^
  File "/usr/local/lib/python3.11/site-packages/airflow/utils/operator_helpers.py", line 252, in run
    return self.func(*args, **kwargs)
           ^^^^^^^^^^^^^^^^^^^^^^^^^^
  File "/usr/local/lib/python3.11/site-packages/airflow/models/baseoperator.py", line 406, in wrapper
    return func(self, *args, **kwargs)
           ^^^^^^^^^^^^^^^^^^^^^^^^^^^
  File "/usr/local/lib/python3.11/site-packages/airflow/providers/common/sql/operators/sql.py", line 284, in execute
    output = hook.run(
             ^^^^^^^^^
  File "/usr/local/lib/python3.11/site-packages/airflow/providers/common/sql/hooks/sql.py", line 489, in run
    self._run_command(cur, sql_statement, parameters)
  File "/usr/local/lib/python3.11/site-packages/airflow/providers/common/sql/hooks/sql.py", line 549, in _run_command
    cur.execute(sql_statement)
psycopg2.errors.DuplicateTable: relation "gpu_specs_11_2024" already exists

[2024-11-05T15:34:47.606+0000] {local_task_job_runner.py:266} INFO - Task exited with return code 1
[2024-11-05T15:34:47.620+0000] {logging_mixin.py:190} WARNING - /usr/local/lib/python3.11/site-packages/***/models/baseoperator.py:1378 AirflowProviderDeprecationWarning: Call to deprecated class PostgresOperator. (Please use `***.providers.common.sql.operators.sql.SQLExecuteQueryOperator`.Also, you can provide `hook_params={'schema': <database>}`.)
[2024-11-05T15:34:47.630+0000] {taskinstance.py:3900} INFO - 0 downstream tasks scheduled from follow-on schedule check
[2024-11-05T15:34:47.632+0000] {local_task_job_runner.py:245} INFO - ::endgroup::
