[2024-11-06T08:17:56.438+0000] {local_task_job_runner.py:123} INFO - ::group::Pre task execution logs
[2024-11-06T08:17:56.592+0000] {taskinstance.py:2612} INFO - Dependencies all met for dep_context=non-requeueable deps ti=<TaskInstance: main_dag.database_tasks.check_integrity manual__2024-11-06T06:42:05.001646+00:00 [queued]>
[2024-11-06T08:17:56.600+0000] {taskinstance.py:2612} INFO - Dependencies all met for dep_context=requeueable deps ti=<TaskInstance: main_dag.database_tasks.check_integrity manual__2024-11-06T06:42:05.001646+00:00 [queued]>
[2024-11-06T08:17:56.600+0000] {taskinstance.py:2865} INFO - Starting attempt 1 of 2
[2024-11-06T08:17:56.613+0000] {taskinstance.py:2888} INFO - Executing <Task(PythonOperator): database_tasks.check_integrity> on 2024-11-06 06:42:05.001646+00:00
[2024-11-06T08:17:56.618+0000] {standard_task_runner.py:72} INFO - Started process 21972 to run task
[2024-11-06T08:17:56.620+0000] {standard_task_runner.py:104} INFO - Running: ['***', 'tasks', 'run', 'main_dag', 'database_tasks.check_integrity', 'manual__2024-11-06T06:42:05.001646+00:00', '--job-id', '21', '--raw', '--subdir', 'DAGS_FOLDER/main_dag.py', '--cfg-path', '/tmp/tmpu3mxzshu']
[2024-11-06T08:17:56.621+0000] {standard_task_runner.py:105} INFO - Job 21: Subtask database_tasks.check_integrity
[2024-11-06T08:17:56.677+0000] {task_command.py:467} INFO - Running <TaskInstance: main_dag.database_tasks.check_integrity manual__2024-11-06T06:42:05.001646+00:00 [running]> on host 9694314923d2
[2024-11-06T08:17:56.769+0000] {taskinstance.py:3131} INFO - Exporting env vars: AIRFLOW_CTX_DAG_OWNER='veil' AIRFLOW_CTX_DAG_ID='main_dag' AIRFLOW_CTX_TASK_ID='database_tasks.check_integrity' AIRFLOW_CTX_EXECUTION_DATE='2024-11-06T06:42:05.001646+00:00' AIRFLOW_CTX_TRY_NUMBER='1' AIRFLOW_CTX_DAG_RUN_ID='manual__2024-11-06T06:42:05.001646+00:00'
[2024-11-06T08:17:56.770+0000] {taskinstance.py:731} INFO - ::endgroup::
[2024-11-06T08:17:56.790+0000] {logging_mixin.py:190} INFO - Connection to PostgreSQL DB successful
[2024-11-06T08:17:56.791+0000] {logging_mixin.py:190} INFO - /app/***/dags/database/integrity_check.py
[2024-11-06T08:17:56.808+0000] {taskinstance.py:3310} ERROR - Task failed with exception
Traceback (most recent call last):
  File "/usr/local/lib/python3.11/site-packages/airflow/models/taskinstance.py", line 767, in _execute_task
    result = _execute_callable(context=context, **execute_callable_kwargs)
             ^^^^^^^^^^^^^^^^^^^^^^^^^^^^^^^^^^^^^^^^^^^^^^^^^^^^^^^^^^^^^
  File "/usr/local/lib/python3.11/site-packages/airflow/models/taskinstance.py", line 733, in _execute_callable
    return ExecutionCallableRunner(
           ^^^^^^^^^^^^^^^^^^^^^^^^
  File "/usr/local/lib/python3.11/site-packages/airflow/utils/operator_helpers.py", line 252, in run
    return self.func(*args, **kwargs)
           ^^^^^^^^^^^^^^^^^^^^^^^^^^
  File "/usr/local/lib/python3.11/site-packages/airflow/models/baseoperator.py", line 406, in wrapper
    return func(self, *args, **kwargs)
           ^^^^^^^^^^^^^^^^^^^^^^^^^^^
  File "/usr/local/lib/python3.11/site-packages/airflow/operators/python.py", line 238, in execute
    return_value = self.execute_callable()
                   ^^^^^^^^^^^^^^^^^^^^^^^
  File "/usr/local/lib/python3.11/site-packages/airflow/operators/python.py", line 256, in execute_callable
    return runner.run(*self.op_args, **self.op_kwargs)
           ^^^^^^^^^^^^^^^^^^^^^^^^^^^^^^^^^^^^^^^^^^^
  File "/usr/local/lib/python3.11/site-packages/airflow/utils/operator_helpers.py", line 252, in run
    return self.func(*args, **kwargs)
           ^^^^^^^^^^^^^^^^^^^^^^^^^^
  File "/app/airflow/dags/database/integrity_check.py", line 130, in check_integrity_all
    _check_integrity(conn,
  File "/app/airflow/dags/database/integrity_check.py", line 50, in _check_integrity
    tmp_data = json.load(open(tmp_data_path))
               ^^^^^^^^^^^^^^^^^^^^^^^^^^^^^^
  File "/usr/local/lib/python3.11/json/__init__.py", line 293, in load
    return loads(fp.read(),
           ^^^^^^^^^^^^^^^^
  File "/usr/local/lib/python3.11/json/__init__.py", line 346, in loads
    return _default_decoder.decode(s)
           ^^^^^^^^^^^^^^^^^^^^^^^^^^
  File "/usr/local/lib/python3.11/json/decoder.py", line 337, in decode
    obj, end = self.raw_decode(s, idx=_w(s, 0).end())
               ^^^^^^^^^^^^^^^^^^^^^^^^^^^^^^^^^^^^^^
  File "/usr/local/lib/python3.11/json/decoder.py", line 355, in raw_decode
    raise JSONDecodeError("Expecting value", s, err.value) from None
json.decoder.JSONDecodeError: Expecting value: line 792 column 1 (char 601939)
[2024-11-06T08:17:56.829+0000] {taskinstance.py:1225} INFO - Marking task as UP_FOR_RETRY. dag_id=main_dag, task_id=database_tasks.check_integrity, run_id=manual__2024-11-06T06:42:05.001646+00:00, execution_date=20241106T064205, start_date=20241106T081756, end_date=20241106T081756
[2024-11-06T08:17:56.844+0000] {taskinstance.py:340} INFO - ::group::Post task execution logs
[2024-11-06T08:17:56.845+0000] {standard_task_runner.py:124} ERROR - Failed to execute job 21 for task database_tasks.check_integrity (Expecting value: line 792 column 1 (char 601939); 21972)
Traceback (most recent call last):
  File "/usr/local/lib/python3.11/site-packages/airflow/task/task_runner/standard_task_runner.py", line 117, in _start_by_fork
    ret = args.func(args, dag=self.dag)
          ^^^^^^^^^^^^^^^^^^^^^^^^^^^^^
  File "/usr/local/lib/python3.11/site-packages/airflow/cli/cli_config.py", line 49, in command
    return func(*args, **kwargs)
           ^^^^^^^^^^^^^^^^^^^^^
  File "/usr/local/lib/python3.11/site-packages/airflow/utils/cli.py", line 115, in wrapper
    return f(*args, **kwargs)
           ^^^^^^^^^^^^^^^^^^
  File "/usr/local/lib/python3.11/site-packages/airflow/cli/commands/task_command.py", line 483, in task_run
    task_return_code = _run_task_by_selected_method(args, _dag, ti)
                       ^^^^^^^^^^^^^^^^^^^^^^^^^^^^^^^^^^^^^^^^^^^^
  File "/usr/local/lib/python3.11/site-packages/airflow/cli/commands/task_command.py", line 256, in _run_task_by_selected_method
    return _run_raw_task(args, ti)
           ^^^^^^^^^^^^^^^^^^^^^^^
  File "/usr/local/lib/python3.11/site-packages/airflow/cli/commands/task_command.py", line 341, in _run_raw_task
    return ti._run_raw_task(
           ^^^^^^^^^^^^^^^^^
  File "/usr/local/lib/python3.11/site-packages/airflow/utils/session.py", line 97, in wrapper
    return func(*args, session=session, **kwargs)
           ^^^^^^^^^^^^^^^^^^^^^^^^^^^^^^^^^^^^^^
  File "/usr/local/lib/python3.11/site-packages/airflow/models/taskinstance.py", line 3004, in _run_raw_task
    return _run_raw_task(
           ^^^^^^^^^^^^^^
  File "/usr/local/lib/python3.11/site-packages/airflow/models/taskinstance.py", line 273, in _run_raw_task
    TaskInstance._execute_task_with_callbacks(
  File "/usr/local/lib/python3.11/site-packages/airflow/models/taskinstance.py", line 3158, in _execute_task_with_callbacks
    result = self._execute_task(context, task_orig)
             ^^^^^^^^^^^^^^^^^^^^^^^^^^^^^^^^^^^^^^
  File "/usr/local/lib/python3.11/site-packages/airflow/models/taskinstance.py", line 3182, in _execute_task
    return _execute_task(self, context, task_orig)
           ^^^^^^^^^^^^^^^^^^^^^^^^^^^^^^^^^^^^^^^
  File "/usr/local/lib/python3.11/site-packages/airflow/models/taskinstance.py", line 767, in _execute_task
    result = _execute_callable(context=context, **execute_callable_kwargs)
             ^^^^^^^^^^^^^^^^^^^^^^^^^^^^^^^^^^^^^^^^^^^^^^^^^^^^^^^^^^^^^
  File "/usr/local/lib/python3.11/site-packages/airflow/models/taskinstance.py", line 733, in _execute_callable
    return ExecutionCallableRunner(
           ^^^^^^^^^^^^^^^^^^^^^^^^
  File "/usr/local/lib/python3.11/site-packages/airflow/utils/operator_helpers.py", line 252, in run
    return self.func(*args, **kwargs)
           ^^^^^^^^^^^^^^^^^^^^^^^^^^
  File "/usr/local/lib/python3.11/site-packages/airflow/models/baseoperator.py", line 406, in wrapper
    return func(self, *args, **kwargs)
           ^^^^^^^^^^^^^^^^^^^^^^^^^^^
  File "/usr/local/lib/python3.11/site-packages/airflow/operators/python.py", line 238, in execute
    return_value = self.execute_callable()
                   ^^^^^^^^^^^^^^^^^^^^^^^
  File "/usr/local/lib/python3.11/site-packages/airflow/operators/python.py", line 256, in execute_callable
    return runner.run(*self.op_args, **self.op_kwargs)
           ^^^^^^^^^^^^^^^^^^^^^^^^^^^^^^^^^^^^^^^^^^^
  File "/usr/local/lib/python3.11/site-packages/airflow/utils/operator_helpers.py", line 252, in run
    return self.func(*args, **kwargs)
           ^^^^^^^^^^^^^^^^^^^^^^^^^^
  File "/app/airflow/dags/database/integrity_check.py", line 130, in check_integrity_all
    _check_integrity(conn,
  File "/app/airflow/dags/database/integrity_check.py", line 50, in _check_integrity
    tmp_data = json.load(open(tmp_data_path))
               ^^^^^^^^^^^^^^^^^^^^^^^^^^^^^^
  File "/usr/local/lib/python3.11/json/__init__.py", line 293, in load
    return loads(fp.read(),
           ^^^^^^^^^^^^^^^^
  File "/usr/local/lib/python3.11/json/__init__.py", line 346, in loads
    return _default_decoder.decode(s)
           ^^^^^^^^^^^^^^^^^^^^^^^^^^
  File "/usr/local/lib/python3.11/json/decoder.py", line 337, in decode
    obj, end = self.raw_decode(s, idx=_w(s, 0).end())
               ^^^^^^^^^^^^^^^^^^^^^^^^^^^^^^^^^^^^^^
  File "/usr/local/lib/python3.11/json/decoder.py", line 355, in raw_decode
    raise JSONDecodeError("Expecting value", s, err.value) from None
json.decoder.JSONDecodeError: Expecting value: line 792 column 1 (char 601939)
[2024-11-06T08:17:56.881+0000] {local_task_job_runner.py:266} INFO - Task exited with return code 1
[2024-11-06T08:17:56.899+0000] {taskinstance.py:3900} INFO - 0 downstream tasks scheduled from follow-on schedule check
[2024-11-06T08:17:56.901+0000] {local_task_job_runner.py:245} INFO - ::endgroup::
